<?xml version="1.0"?>
<robot xmlns:xacro="http://www.ros.org/wiki/xacro" name="forklift">

    <link name="base_footprint"/>

    <link name="base_link">
        <inertial>
            <origin xyz="0.0 0.0 0.0" rpy="0.0 0.0 0.0"/>
            <mass value="50.0"/>
            <inertia ixx="0.0" ixy="0.0" ixz="0.0" iyy="0.0" iyz="0.0" izz="0.0"/>
        </inertial>
        <visual name="">
            <origin xyz="0.0 0.0 0.0" rpy="0.0 0.0 0.0"/>
            <geometry>
                <box size="0.525 0.525 0.2155"/>
            </geometry>
            <material name="blue">
                <color rgba="0.0 0.0 1.0 1.0"/>
                <texture filename=""/>
            </material>
        </visual>
        <collision>
            <origin xyz="0.0 0.0 0.0" rpy="0.0 0.0 0.0"/>
            <geometry>
                <box size="0.525 0.525 0.2155"/>
            </geometry>
        </collision>
    </link>
    <joint name="base_joint" type="fixed">
        <origin xyz="0.0 0.0 0.0" rpy="0.0 0.0 0.0"/>
        <parent link="base_footprint"/>
        <child link="base_link"/>
    </joint>

<!--    ***   wheels   ***   -->    

    <xacro:macro name="wheel" params="name x y">
        <link name="wheel_link_${name}">
            <inertial>
                <origin xyz="0.0 0.0 0.0" rpy="0.0 0.0 0.0"/>
                <mass value="1.0"/>
                <inertia ixx="0.0" ixy="0.0" ixz="0.0" iyy="0.0" iyz="0.0" izz="0.0"/>        </inertial>
            <visual name="">
                <origin xyz="0.0 0.0 0.0" rpy="0.0 0.0 0.0"/>
                <geometry>
                    <cylinder radius="0.06" length="0.02"/>
                </geometry>
                <material name="black">
                    <color rgba="0.0 0.0 0.0 1.0"/>
                    <texture filename=""/>
                </material>
            </visual>
            <collision>
                <origin xyz="0.0 0.0 0.0" rpy="0.0 0.0 0.0"/>
                <geometry>
                    <cylinder radius="0.06" length="0.02"/>
                </geometry>
            </collision>
        </link>

        <joint name="wheel_joint_${name}" type="continuous">
            <origin xyz="${x} ${y} -0.100250" rpy="1.57 0.0 0.0"/>
            <parent link="base_link"/>
            <child link="wheel_link_${name}"/>
            <axis xyz="0.0 0.0 1.0"/>
        </joint>
    </xacro:macro>

<!--   ***   fork base   ***   -->
    <xacro:macro name="fork_base" params="name y">
        <link name="forkbase_link_${name}">
            <inertial>
                <origin xyz="0.0 0.0 0.0" rpy="0.0 0.0 0.0"/>
                <mass value="0.5"/>
                <inertia ixx="0.0" ixy="0.0" ixz="0.0" iyy="0.0" iyz="0.0" izz="0.0"/>
            </inertial>
            <visual name="">
                <origin xyz="0.0 0.0 0.0" rpy="0.0 0.0 0.0"/>
                <geometry>
                    <box size="0.01 0.05 0.1"/>
                </geometry>
                <material name="green">
                    <color rgba="0.0 1.0 0.0 1.0"/>
                    <texture filename=""/>
                </material>
            </visual>
            <collision>
                <origin xyz="0.0 0.0 0.0" rpy="0.0 0.0 0.0"/>
                <geometry>
                    <box size="0.01 0.05 0.1"/>
                </geometry>
            </collision>
        </link>

        <joint name="forkbase_link_${name}" type="fixed">
            <origin xyz="0.2675 ${y} -0.10025" rpy="0.0 0.0 0.0"/>
            <parent link="base_link"/>
            <child link="forkbase_link_${name}"/>
        </joint>
    </xacro:macro>

<!--   ***   fork   ***   -->
    <xacro:macro name="fork_link" params="name">
        <link name="fork_link_${name}">
            <inertial>
                <origin xyz="0.0 0.0 0.0" rpy="0.0 0.0 0.0"/>
                <mass value="0.5"/>
                <inertia ixx="0.0" ixy="0.0" ixz="0.0" iyy="0.0" iyz="0.0" izz="0.0"/>
            </inertial>
            <visual name="">
                <origin xyz="0.0 0.0 0.0" rpy="0.0 0.0 0.0"/>
                <geometry>
                    <box size="0.25 0.05 0.01"/>
                </geometry>
                <material name="green">
                    <color rgba="0.0 1.0 0.0 1.0"/>
                    <texture filename=""/>
                </material>
            </visual>
            <collision>
                <origin xyz="0.0 0.0 0.0" rpy="0.0 0.0 0.0"/>
                <geometry>
                    <box size="0.25 0.05 0.01"/>
                </geometry>
            </collision>
        </link>

        <joint name="fork_link_${name}" type="fixed">
            <origin xyz="0.13 0 -0.045" rpy="0.0 0.0 0.0"/>
            <parent link="forkbase_link_${name}"/>
            <child link="fork_link_${name}"/>
        </joint>
    </xacro:macro>

<!--   ***   combine component   ***   -->
    <xacro:wheel name="back_right" x="-0.272513" y ="-0.272513"/>
    <xacro:wheel name="back_left" x="-0.150000" y ="0.272513"/>
    <xacro:wheel name="front_right" x="0.150000" y ="-0.272513"/>
    <xacro:wheel name="front_left" x="0.150000" y ="0.272513"/>

    <xacro:fork_base name="right" y ="-0.055"/>
    <xacro:fork_base name="left" y ="0.055"/>

    <xacro:fork_link name="right"/>
    <xacro:fork_link name="left"/>

</robot>